2019-07-03 16:23:37,560 [ERROR]  Experienced exception while trying to serve
Traceback (most recent call last):
  File "c:\users\admin\appdata\local\programs\python\python36\lib\site-packages\sanic\app.py", line 1096, in run
    serve(**server_settings)
  File "c:\users\admin\appdata\local\programs\python\python36\lib\site-packages\sanic\server.py", line 770, in serve
    loop.run_forever()
  File "c:\users\admin\appdata\local\programs\python\python36\lib\asyncio\base_events.py", line 438, in run_forever
    self._run_once()
  File "c:\users\admin\appdata\local\programs\python\python36\lib\asyncio\base_events.py", line 1415, in _run_once
    event_list = self._selector.select(timeout)
  File "c:\users\admin\appdata\local\programs\python\python36\lib\selectors.py", line 323, in select
    r, w, _ = self._select(self._readers, self._writers, [], timeout)
  File "c:\users\admin\appdata\local\programs\python\python36\lib\selectors.py", line 314, in _select
    r, w, x = select.select(r, w, w, timeout)
  File "c:\users\admin\appdata\local\programs\python\python36\lib\site-packages\socketio\client.py", line 25, in signal_handler
    return original_signal_handler(sig, frame)
  File "c:\users\admin\appdata\local\programs\python\python36\lib\site-packages\engineio\client.py", line 41, in signal_handler
    return original_signal_handler(sig, frame)
KeyboardInterrupt
